Workbook

Sheet REALIZADO POR...

Sheet LISTA DE PRECIOS MATERIALES
A1: INGREDIENTES | B1: UND | C1: PRECIO / unidad | D1: Columna14 | E1: Columna15 | F1: Columna16 | G1: Columna17 | H1: Columna18 | I1: Columna19 | J1: Columna20 | K1: Columna21 | L1: Columna22 | M1: Columna23 | N1: Columna25 | O1: Columna26 | P1: Columna27 | Q1: Columna28 | R1: Columna29 | S1: Columna30 | T1: Columna31 | U1: Columna32 | V1: Columna33 | W1: Columna34 | X1: Columna35 | Y1: Columna36 | Z1: Columna37 | AA1: Columna38 | AB1: Columna39 | AC1: Columna40 | AD1: Columna41 | AE1: Columna42 | AF1: Columna43 | AG1: Columna44 | AH1: Columna45 | AI1: Columna46 | AJ1: Columna47 | AK1: Columna48 | AL1: Columna49 | AM1: Columna50 | AN1: Columna51 | AO1: Columna52 | AP1: Columna53 | AQ1: Columna54 | AR1: Columna55 | AS1: Columna56 | AT1: Columna57 | AU1: Columna58 | AV1: Columna59 | AW1: Columna60 | AX1: Columna61 | AY1: Columna62 | AZ1: Columna63 | BA1: Columna64 | BB1: Columna65 | BC1: Columna66 | BD1: Columna67 | BE1: Columna68 | BF1: Columna69 | BG1: Columna70 | BH1: Columna71 | BI1: Columna72 | BJ1: Columna73 | BK1: Columna74 | BL1: Columna75 | BM1: Columna76 | BN1: Columna77 | BO1: Columna78 | BP1: Columna79 | BQ1: Columna80 | BR1: Columna81 | BS1: Columna82 | BT1: Columna83 | BU1: Columna84 | BV1: Columna85 | BW1: Columna86 | BX1: Columna87 | BY1: Columna88 | BZ1: Columna89 | CA1: Columna90 | CB1: Columna91 | CC1: Columna92 | CD1: Columna93 | CE1: Columna94 | CF1: Columna95 | CG1: Columna96 | CH1: Columna97 | CI1: Columna98 | CJ1: Columna99 | CK1: Columna100 | CL1: Columna101 | CM1: Columna102 | CN1: Columna103 | CO1: Columna104 | CP1: Columna105 | CQ1: Columna106 | CR1: Columna107 | CS1: Columna108 | CT1: Columna109 | CU1: Columna110 | CV1: Columna111 | CW1: Columna112 | CX1: Columna113 | CY1: Columna114 | CZ1: Columna115 | DA1: Columna116 | DB1: Columna117 | DC1: Columna118 | DD1: Columna119 | DE1: Columna120 | DF1: Columna121 | DG1: Columna122 | DH1: Columna123 | DI1: Columna124 | DJ1: Columna125 | DK1: Columna126 | DL1: Columna127 | DM1: Columna128 | DN1: Columna129 | DO1: Columna130 | DP1: Columna131 | DQ1: Columna132 | DR1: Columna133 | DS1: Columna134 | DT1: Columna135 | DU1: Columna136 | DV1: Columna137 | DW1: Columna138 | DX1: Columna139 | DY1: Columna140 | DZ1: Columna141 | EA1: Columna142 | EB1: Columna143 | EC1: Columna144 | ED1: Columna145 | EE1: Columna146 | EF1: Columna147 | EG1: Columna148 | EH1: Columna149 | EI1: Columna150 | EJ1: Columna151 | EK1: Columna152 | EL1: Columna153 | EM1: Columna154 | EN1: Columna155 | EO1: Columna156 | EP1: Columna157 | EQ1: Columna158 | ER1: Columna159 | ES1: Columna160 | ET1: Columna161 | EU1: Columna162 | EV1: Columna163 | EW1: Columna164 | EX1: Columna165 | EY1: Columna166 | EZ1: Columna167 | FA1: Columna168 | FB1: Columna169 | FC1: Columna170 | FD1: Columna171 | FE1: Columna172 | FF1: Columna173 | FG1: Columna174 | FH1: Columna175 | FI1: Columna176 | FJ1: Columna177 | FK1: Columna178 | FL1: Columna179 | FM1: Columna180 | FN1: Columna181 | FO1: Columna182 | FP1: Columna183 | FQ1: Columna184 | FR1: Columna185 | FS1: Columna186 | FT1: Columna187 | FU1: Columna188 | FV1: Columna189 | FW1: Columna190 | FX1: Columna191 | FY1: Columna192 | FZ1: Columna193 | GA1: Columna194 | GB1: Columna195 | GC1: Columna196 | GD1: Columna197 | GE1: Columna198 | GF1: Columna199 | GG1: Columna200 | GH1: Columna201 | GI1: Columna202 | GJ1: Columna203 | GK1: Columna204 | GL1: Columna205 | GM1: Columna206 | GN1: Columna207 | GO1: Columna208 | GP1: Columna209 | GQ1: Columna210 | GR1: Columna211 | GS1: Columna212 | GT1: Columna213 | GU1: Columna214 | GV1: Columna215 | GW1: Columna216 | GX1: Columna217 | GY1: Columna218 | GZ1: Columna219 | HA1: Columna220 | HB1: Columna221 | HC1: Columna222 | HD1: Columna223 | HE1: Columna224 | HF1: Columna225 | HG1: Columna226 | HH1: Columna227 | HI1: Columna228 | HJ1: Columna229 | HK1: Columna230 | HL1: Columna231 | HM1: Columna232 | HN1: Columna233 | HO1: Columna234 | HP1: Columna235 | HQ1: Columna236 | HR1: Columna237 | HS1: Columna238 | HT1: Columna239 | HU1: Columna240 | HV1: Columna241 | HW1: Columna242 | HX1: Columna243 | HY1: Columna244 | HZ1: Columna245 | IA1: Columna246 | IB1: Columna247 | IC1: Columna248 | ID1: Columna249 | IE1: Columna250 | IF1: Columna251 | IG1: Columna252 | IH1: Columna253 | II1: Columna254 | IJ1: Columna255 | IK1: Columna256 | IL1: Columna257 | IM1: Columna258 | IN1: Columna259 | IO1: Columna260 | IP1: Columna261 | IQ1: Columna262 | IR1: Columna263 | IS1: Columna264 | IT1: Columna265 | IU1: Columna266 | IV1: Columna267 | IW1: Columna268 | IX1: Columna269 | IY1: Columna270 | IZ1: Columna271 | JA1: Columna272 | JB1: Columna273 | JC1: Columna274 | JD1: Columna275 | JE1: Columna276 | JF1: Columna277 | JG1: Columna278 | JH1: Columna279 | JI1: Columna280 | JJ1: Columna281 | JK1: Columna282 | JL1: Columna283 | JM1: Columna284 | JN1: Columna285 | JO1: Columna286 | JP1: Columna287 | JQ1: Columna288 | JR1: Columna289 | JS1: Columna290 | JT1: Columna291 | JU1: Columna292 | JV1: Columna293 | JW1: Columna294 | JX1: Columna295 | JY1: Columna296 | JZ1: Columna297 | KA1: Columna298 | KB1: Columna299 | KC1: Columna300 | KD1: Columna301 | KE1: Columna302 | KF1: Columna303 | KG1: Columna304 | KH1: Columna305 | KI1: Columna306 | KJ1: Columna307 | KK1: Columna308 | KL1: Columna309 | KM1: Columna310 | KN1: Columna311 | KO1: Columna312 | KP1: Columna313 | KQ1: Columna314 | KR1: Columna315 | KS1: Columna316 | KT1: Columna317 | KU1: Columna318 | KV1: Columna319 | KW1: Columna320 | KX1: Columna321 | KY1: Columna322 | KZ1: Columna323 | LA1: Columna324 | LB1: Columna325 | LC1: Columna326 | LD1: Columna327 | LE1: Columna328 | LF1: Columna329 | LG1: Columna330 | LH1: Columna331 | LI1: Columna332 | LJ1: Columna333 | LK1: Columna334 | LL1: Columna335 | LM1: Columna336 | LN1: Columna337 | LO1: Columna338 | LP1: Columna339 | LQ1: Columna340 | LR1: Columna341 | LS1: Columna342 | LT1: Columna343 | LU1: Columna344 | LV1: Columna345 | LW1: Columna346 | LX1: Columna347 | LY1: Columna348 | LZ1: Columna349 | MA1: Columna350 | MB1: Columna351 | MC1: Columna352 | MD1: Columna353 | ME1: Columna354 | MF1: Columna355 | MG1: Columna356 | MH1: Columna357 | MI1: Columna358 | MJ1: Columna359 | MK1: Columna360 | ML1: Columna361 | MM1: Columna362 | MN1: Columna363 | MO1: Columna364 | MP1: Columna365 | MQ1: Columna366 | MR1: Columna367 | MS1: Columna368 | MT1: Columna369 | MU1: Columna370 | MV1: Columna371 | MW1: Columna372 | MX1: Columna373 | MY1: Columna374 | MZ1: Columna375 | NA1: Columna376 | NB1: Columna377 | NC1: Columna378 | ND1: Columna379 | NE1: Columna380 | NF1: Columna381 | NG1: Columna382 | NH1: Columna383 | NI1: Columna384 | NJ1: Columna385 | NK1: Columna386 | NL1: Columna387 | NM1: Columna388 | NN1: Columna389 | NO1: Columna390 | NP1: Columna391 | NQ1: Columna392 | NR1: Columna393 | NS1: Columna394 | NT1: Columna395 | NU1: Columna396 | NV1: Columna397 | NW1: Columna398 | NX1: Columna399 | NY1: Columna400 | NZ1: Columna401 | OA1: Columna402 | OB1: Columna403 | OC1: Columna404 | OD1: Columna405 | OE1: Columna406 | OF1: Columna407 | OG1: Columna408 | OH1: Columna409 | OI1: Columna410 | OJ1: Columna411 | OK1: Columna412 | OL1: Columna413 | OM1: Columna414 | ON1: Columna415 | OO1: Columna416 | OP1: Columna417 | OQ1: Columna418 | OR1: Columna419 | OS1: Columna420 | OT1: Columna421 | OU1: Columna422 | OV1: Columna423 | OW1: Columna424 | OX1: Columna425 | OY1: Columna426 | OZ1: Columna427 | PA1: Columna428 | PB1: Columna429 | PC1: Columna430 | PD1: Columna431 | PE1: Columna432 | PF1: Columna433 | PG1: Columna434 | PH1: Columna435 | PI1: Columna436 | PJ1: Columna437 | PK1: Columna438 | PL1: Columna439 | PM1: Columna440 | PN1: Columna441 | PO1: Columna442 | PP1: Columna443 | PQ1: Columna444 | PR1: Columna445 | PS1: Columna446 | PT1: Columna447 | PU1: Columna448 | PV1: Columna449 | PW1: Columna450 | PX1: Columna451 | PY1: Columna452 | PZ1: Columna453 | QA1: Columna454 | QB1: Columna455 | QC1: Columna456 | QD1: Columna457 | QE1: Columna458 | QF1: Columna459 | QG1: Columna460 | QH1: Columna461 | QI1: Columna462 | QJ1: Columna463 | QK1: Columna464 | QL1: Columna465 | QM1: Columna466 | QN1: Columna467 | QO1: Columna468 | QP1: Columna469 | QQ1: Columna470 | QR1: Columna471 | QS1: Columna472 | QT1: Columna473 | QU1: Columna474 | QV1: Columna475 | QW1: Columna476 | QX1: Columna477 | QY1: Columna478 | QZ1: Columna479 | RA1: Columna480 | RB1: Columna481 | RC1: Columna482 | RD1: Columna483 | RE1: Columna484 | RF1: Columna485 | RG1: Columna486 | RH1: Columna487 | RI1: Columna488 | RJ1: Columna489 | RK1: Columna490 | RL1: Columna491 | RM1: Columna492 | RN1: Columna493 | RO1: Columna494 | RP1: Columna495 | RQ1: Columna496 | RR1: Columna497 | RS1: Columna498 | RT1: Columna499 | RU1: Columna500 | RV1: Columna501 | RW1: Columna502 | RX1: Columna503 | RY1: Columna504 | RZ1: Columna505 | SA1: Columna506 | SB1: Columna507 | SC1: Columna508 | SD1: Columna509 | SE1: Columna510 | SF1: Columna511 | SG1: Columna512 | SH1: Columna513 | SI1: Columna514 | SJ1: Columna515 | SK1: Columna516 | SL1: Columna517 | SM1: Columna518 | SN1: Columna519 | SO1: Columna520 | SP1: Columna521 | SQ1: Columna522 | SR1: Columna523 | SS1: Columna524 | ST1: Columna525 | SU1: Columna526 | SV1: Columna527 | SW1: Columna528 | SX1: Columna529 | SY1: Columna530 | SZ1: Columna531 | TA1: Columna532 | TB1: Columna533 | TC1: Columna534 | TD1: Columna535 | TE1: Columna536 | TF1: Columna537 | TG1: Columna538 | TH1: Columna539 | TI1: Columna540 | TJ1: Columna541 | TK1: Columna542 | TL1: Columna543 | TM1: Columna544 | TN1: Columna545 | TO1: Columna546 | TP1: Columna547 | TQ1: Columna548 | TR1: Columna549 | TS1: Columna550 | TT1: Columna551 | TU1: Columna552 | TV1: Columna553 | TW1: Columna554 | TX1: Columna555 | TY1: Columna556 | TZ1: Columna557 | UA1: Columna558 | UB1: Columna559 | UC1: Columna560 | UD1: Columna561 | UE1: Columna562 | UF1: Columna563 | UG1: Columna564 | UH1: Columna565 | UI1: Columna566 | UJ1: Columna567 | UK1: Columna568 | UL1: Columna569 | UM1: Columna570 | UN1: Columna571 | UO1: Columna572 | UP1: Columna573 | UQ1: Columna574 | UR1: Columna575 | US1: Columna576 | UT1: Columna577 | UU1: Columna578 | UV1: Columna579 | UW1: Columna580 | UX1: Columna581 | UY1: Columna582 | UZ1: Columna583 | VA1: Columna584 | VB1: Columna585 | VC1: Columna586 | VD1: Columna587 | VE1: Columna588 | VF1: Columna589 | VG1: Columna590 | VH1: Columna591 | VI1: Columna592 | VJ1: Columna593 | VK1: Columna594 | VL1: Columna595 | VM1: Columna596 | VN1: Columna597 | VO1: Columna598 | VP1: Columna599 | VQ1: Columna600 | VR1: Columna601 | VS1: Columna602 | VT1: Columna603 | VU1: Columna604 | VV1: Columna605 | VW1: Columna606 | VX1: Columna607 | VY1: Columna608 | VZ1: Columna609 | WA1: Columna610 | WB1: Columna611 | WC1: Columna612 | WD1: Columna613 | WE1: Columna614 | WF1: Columna615 | WG1: Columna616 | WH1: Columna617 | WI1: Columna618 | WJ1: Columna619 | WK1: Columna620 | WL1: Columna621 | WM1: Columna622 | WN1: Columna623 | WO1: Columna624 | WP1: Columna625 | WQ1: Columna626 | WR1: Columna627 | WS1: Columna628 | WT1: Columna629 | WU1: Columna630 | WV1: Columna631 | WW1: Columna632 | WX1: Columna633 | WY1: Columna634 | WZ1: Columna635 | XA1: Columna636 | XB1: Columna637 | XC1: Columna638 | XD1: Columna639 | XE1: Columna640 | XF1: Columna641 | XG1: Columna642 | XH1: Columna643 | XI1: Columna644 | XJ1: Columna645 | XK1: Columna646 | XL1: Columna647 | XM1: Columna648 | XN1: Columna649 | XO1: Columna650 | XP1: Columna651 | XQ1: Columna652 | XR1: Columna653 | XS1: Columna654 | XT1: Columna655 | XU1: Columna656 | XV1: Columna657 | XW1: Columna658 | XX1: Columna659 | XY1: Columna660 | XZ1: Columna661 | YA1: Columna662 | YB1: Columna663 | YC1: Columna664 | YD1: Columna665 | YE1: Columna666 | YF1: Columna667 | YG1: Columna668 | YH1: Columna669 | YI1: Columna670 | YJ1: Columna671 | YK1: Columna672 | YL1: Columna673 | YM1: Columna674 | YN1: Columna675 | YO1: Columna676 | YP1: Columna677 | YQ1: Columna678 | YR1: Columna679 | YS1: Columna680 | YT1: Columna681 | YU1: Columna682 | YV1: Columna683 | YW1: Columna684 | YX1: Columna685 | YY1: Columna686 | YZ1: Columna687 | ZA1: Columna688 | ZB1: Columna689 | ZC1: Columna690 | ZD1: Columna691 | ZE1: Columna692 | ZF1: Columna693 | ZG1: Columna694 | ZH1: Columna695 | ZI1: Columna696 | ZJ1: Columna697 | ZK1: Columna698 | ZL1: Columna699 | ZM1: Columna700 | ZN1: Columna701 | ZO1: Columna702 | ZP1: Columna703 | ZQ1: Columna704 | ZR1: Columna705 | ZS1: Columna706 | ZT1: Columna707 | ZU1: Columna708 | ZV1: Columna709 | ZW1: Columna710 | ZX1: Columna711 | ZY1: Columna712 | ZZ1: Columna713 | AAA1: Columna714 | AAB1: Columna715 | AAC1: Columna716 | AAD1: Columna717 | AAE1: Columna718 | AAF1: Columna719 | AAG1: Columna720 | AAH1: Columna721 | AAI1: Columna722 | AAJ1: Columna723 | AAK1: Columna724 | AAL1: Columna725 | AAM1: Columna726 | AAN1: Columna727 | AAO1: Columna728 | AAP1: Columna729 | AAQ1: Columna730 | AAR1: Columna731 | AAS1: Columna732 | AAT1: Columna733 | AAU1: Columna734 | AAV1: Columna735 | AAW1: Columna736 | AAX1: Columna737 | AAY1: Columna738 | AAZ1: Columna739 | ABA1: Columna740 | ABB1: Columna741 | ABC1: Columna742 | ABD1: Columna743 | ABE1: Columna744 | ABF1: Columna745 | ABG1: Columna746 | ABH1: Columna747 | ABI1: Columna748 | ABJ1: Columna749 | ABK1: Columna750 | ABL1: Columna751 | ABM1: Columna752 | ABN1: Columna753 | ABO1: Columna754 | ABP1: Columna755 | ABQ1: Columna756 | ABR1: Columna757 | ABS1: Columna758 | ABT1: Columna759 | ABU1: Columna760 | ABV1: Columna761 | ABW1: Columna762 | ABX1: Columna763 | ABY1: Columna764 | ABZ1: Columna765 | ACA1: Columna766 | ACB1: Columna767 | ACC1: Columna768 | ACD1: Columna769 | ACE1: Columna770 | ACF1: Columna771 | ACG1: Columna772 | ACH1: Columna773 | ACI1: Columna774 | ACJ1: Columna775 | ACK1: Columna776 | ACL1: Columna777 | ACM1: Columna778 | ACN1: Columna779 | ACO1: Columna780 | ACP1: Columna781 | ACQ1: Columna782 | ACR1: Columna783 | ACS1: Columna784 | ACT1: Columna785 | ACU1: Columna786 | ACV1: Columna787 | ACW1: Columna788 | ACX1: Columna789 | ACY1: Columna790 | ACZ1: Columna791 | ADA1: Columna792 | ADB1: Columna793 | ADC1: Columna794 | ADD1: Columna795 | ADE1: Columna796 | ADF1: Columna797 | ADG1: Columna798 | ADH1: Columna799 | ADI1: Columna800 | ADJ1: Columna801 | ADK1: Columna802 | ADL1: Columna803 | ADM1: Columna804 | ADN1: Columna805 | ADO1: Columna806 | ADP1: Columna807 | ADQ1: Columna808 | ADR1: Columna809 | ADS1: Columna810 | ADT1: Columna811 | ADU1: Columna812 | ADV1: Columna813 | ADW1: Columna814 | ADX1: Columna815 | ADY1: Columna816 | ADZ1: Columna817 | AEA1: Columna818 | AEB1: Columna819 | AEC1: Columna820 | AED1: Columna821 | AEE1: Columna822 | AEF1: Columna823 | AEG1: Columna824 | AEH1: Columna825 | AEI1: Columna826 | AEJ1: Columna827 | AEK1: Columna828 | AEL1: Columna829 | AEM1: Columna830 | AEN1: Columna831 | AEO1: Columna832 | AEP1: Columna833 | AEQ1: Columna834 | AER1: Columna835 | AES1: Columna836 | AET1: Columna837 | AEU1: Columna838 | AEV1: Columna839 | AEW1: Columna840 | AEX1: Columna841 | AEY1: Columna842 | AEZ1: Columna843 | AFA1: Columna844 | AFB1: Columna845 | AFC1: Columna846 | AFD1: Columna847 | AFE1: Columna848 | AFF1: Columna849 | AFG1: Columna850 | AFH1: Columna851 | AFI1: Columna852 | AFJ1: Columna853 | AFK1: Columna854 | AFL1: Columna855 | AFM1: Columna856 | AFN1: Columna857 | AFO1: Columna858 | AFP1: Columna859 | AFQ1: Columna860 | AFR1: Columna861 | AFS1: Columna862 | AFT1: Columna863 | AFU1: Columna864 | AFV1: Columna865 | AFW1: Columna866 | AFX1: Columna867 | AFY1: Columna868 | AFZ1: Columna869 | AGA1: Columna870 | AGB1: Columna871 | AGC1: Columna872 | AGD1: Columna873 | AGE1: Columna874 | AGF1: Columna875 | AGG1: Columna876 | AGH1: Columna877 | AGI1: Columna878 | AGJ1: Columna879 | AGK1: Columna880 | AGL1: Columna881 | AGM1: Columna882 | AGN1: Columna883 | AGO1: Columna884 | AGP1: Columna885 | AGQ1: Columna886 | AGR1: Columna887 | AGS1: Columna888 | AGT1: Columna889 | AGU1: Columna890 | AGV1: Columna891 | AGW1: Columna892 | AGX1: Columna893 | AGY1: Columna894 | AGZ1: Columna895 | AHA1: Columna896 | AHB1: Columna897 | AHC1: Columna898 | AHD1: Columna899 | AHE1: Columna900 | AHF1: Columna901 | AHG1: Columna902 | AHH1: Columna903 | AHI1: Columna904 | AHJ1: Columna905 | AHK1: Columna906 | AHL1: Columna907 | AHM1: Columna908 | AHN1: Columna909 | AHO1: Columna910 | AHP1: Columna911 | AHQ1: Columna912 | AHR1: Columna913 | AHS1: Columna914 | AHT1: Columna915 | AHU1: Columna916 | AHV1: Columna917 | AHW1: Columna918 | AHX1: Columna919 | AHY1: Columna920 | AHZ1: Columna921 | AIA1: Columna922 | AIB1: Columna923 | AIC1: Columna924 | AID1: Columna925 | AIE1: Columna926 | AIF1: Columna927 | AIG1: Columna928 | AIH1: Columna929 | AII1: Columna930 | AIJ1: Columna931 | AIK1: Columna932 | AIL1: Columna933 | AIM1: Columna934 | AIN1: Columna935 | AIO1: Columna936 | AIP1: Columna937 | AIQ1: Columna938 | AIR1: Columna939 | AIS1: Columna940 | AIT1: Columna941 | AIU1: Columna942 | AIV1: Columna943 | AIW1: Columna944 | AIX1: Columna945 | AIY1: Columna946 | AIZ1: Columna947 | AJA1: Columna948 | AJB1: Columna949 | AJC1: Columna950 | AJD1: Columna951 | AJE1: Columna952 | AJF1: Columna953 | AJG1: Columna954 | AJH1: Columna955 | AJI1: Columna956 | AJJ1: Columna957 | AJK1: Columna958 | AJL1: Columna959 | AJM1: Columna960 | AJN1: Columna961 | AJO1: Columna962 | AJP1: Columna963 | AJQ1: Columna964 | AJR1: Columna965 | AJS1: Columna966 | AJT1: Columna967 | AJU1: Columna968 | AJV1: Columna969 | AJW1: Columna970 | AJX1: Columna971 | AJY1: Columna972 | AJZ1: Columna973 | AKA1: Columna974 | AKB1: Columna975 | AKC1: Columna976 | AKD1: Columna977 | AKE1: Columna978 | AKF1: Columna979 | AKG1: Columna980 | AKH1: Columna981 | AKI1: Columna982 | AKJ1: Columna983 | AKK1: Columna984 | AKL1: Columna985 | AKM1: Columna986 | AKN1: Columna987 | AKO1: Columna988 | AKP1: Columna989 | AKQ1: Columna990 | AKR1: Columna991 | AKS1: Columna992 | AKT1: Columna993 | AKU1: Columna994 | AKV1: Columna995 | AKW1: Columna996 | AKX1: Columna997 | AKY1: Columna998 | AKZ1: Columna999 | ALA1: Columna1000 | ALB1: Columna1001 | ALC1: Columna1002 | ALD1: Columna1003 | ALE1: Columna1004 | ALF1: Columna1005 | ALG1: Columna1006 | ALH1: Columna1007 | ALI1: Columna1008 | ALJ1: Columna1009 | ALK1: Columna1010 | ALL1: Columna1011 | ALM1: Columna1012 | ALN1: Columna1013 | ALO1: Columna1014 | ALP1: Columna1015 | ALQ1: Columna1016 | ALR1: Columna1017 | ALS1: Columna1018 | ALT1: Columna1019 | ALU1: Columna1020 | ALV1: Columna1021 | ALW1: Columna1022 | ALX1: Columna1023 | ALY1: Columna1024 | ALZ1: Columna1025 | AMA1: Columna1026 | AMB1: Columna1027 | AMC1: Columna1028 | AMD1: Columna1029 | AME1: Columna1030 | AMF1: Columna1031 | AMG1: Columna1032 | AMH1: Columna1033 | AMI1: Columna1034 | AMJ1: Columna1035
A2: Alfileres | B2: caja | C2: 1.49 €
A3: Ambientador eléctrico | B3: unidad | C3: 6.05 €
A4: Artículos de fiesta | B4: unidad | C4: 0.91 €
A5: Bandeja de cartón 22 x 29 cm | B5: unidad | C5: 0.06 €
A6: Bandeja de cartón 40 x 50 cm | B6: unidad | C6: 0.66 €
A7: Bicarbonato | B7: kg | C7: 1.94
A8: Blíster 1000 ml | B8: unidad | C8: 0.37 €
A9: Blonda 26 x 32 cm | B9: unidad | C9: 0.02 €
A10: Blonda 30 x 40 cm | B10: unidad | C10: 0.78 €
A11: Blonda 45 x 55 cm | B11: unidad | C11: 0.10 €
A12: Blonda de parafina 40 x 50 cm | B12: unidad | C12: 0.09 €
A13: Bobina de papel | B13: unidad | C13: 3.80 €
... A58: Spray desmoldeante | B58: unidad | C58: 0.20 €

Sheet LISTA DE PRECIOS INGREDIENTES
A1: INGREDIENTES | B1: UND | C1: PRECIO / unidad | D1: RENDIMIENTO | E1: CATEGORÍA
A2: Abadejo Fresco | B2: kg | C2: 10.50 € | D2: 100.00% | E2: Proteína animal
A3: Abdejo Filete Cong | B3: kg | C3: 4.90 € | D3: 100.00% | E3: Proteína animal
A4: Abdejo Filete Cong Piel | B4: kg | C4: 3.15 € | D4: 100.00% | E4: Proteína animal
A5: Abdejo Filete Cong Prem | B5: kg | C5: 5.20 € | D5: 100.00% | E5: Proteína animal
A6: Aceite Freidoras | B6: kg | C6: 1.01 € | D6: 100.00% | E6: Grasa
A7: Aceite Girasol | B7: kg | C7: 1.04 € | D7: 100.00% | E7: Grasa
A8: Aceite Oliva Virgen Extra | B8: kg | C8: 3.81 € | D8: 100.00% | E8: Grasa
A9: Aceite Oliva Virgen Extra | B9: unidad | C9: 0.22 € | D9: 100.00% | E9: Grasa
A10: Aceite Ove 0´4 º | B10: kg | C10: 3.23 € | D10: 100.00% | E10: Grasa
A11: Aceite De Trufa | B11: kg | C11: 3.60 € | D11: 100.00% | E11: Grasa
A12: Aceituna Negra Con Hueso | B12: kg | C12: 2.00 € | D12: 100.00% | E12: Vegetales y frutas
... A616: Mazapan | B616: kg | C616: 5.96 € | D616: 100.00% | E616: Secos y conservas
A617: Medregal Cong | B617: kg | C617: 45661 | D617: 100.00% | E617: Secos y conservas
A618: Mejillon Cong | B618: kg | C618: 5.20 € | D618: 100.00% | E618: Proteína animal
A619: Mejillon Fresco | B619: kg | C619: 5.20 € | D619: 100.00% | E619: Proteína animal
A620: Mejorana | B620: kg | C620: 6.04 € | D620: 100.00% | E620: Vegetales y frutas
A621: Mejorante Precocinado | B621: kg | C621: 5.30 € | D621: 100.00% | E621: Secos y conservas
A622: Melisa | B622: manojo | C622: 0.70 € | D622: 100.00% | E622: Vegetales y frutas
A623: Melocoton | B623: kg | C623: 1.25 € | D623: 100.00% | E623: Vegetales y frutas
A624: Melocoton Almibar | B624: kg | C624: 0.86 € | D624: 100.00% | E624: Vegetales y frutas
A625: Melon | B625: kg | C625: 0.89 € | D625: 100.00% | E625: Vegetales y frutas
A626: Membrillo | B626: kg | C626: 3.72 € | D626: 100.00% | E626: Vegetales y frutas
A627: Membrillo Porcion | B627: unidad | C627: 4.27 € | D627: 100.00% | E627: Vegetales y frutas
A628: Menestra Cong. | B628: kg | C628: 0.86 € | D628: 100.00% | E628: Vegetales y frutas
A629: Menta | B629: manojo | C629: 0.50 € | D629: 100.00% | E629: Vegetales y frutas
... A690: Neranja Confitada | B690: kg | C690: 3.67 € | D690: 100.00% | E690: Secos y conservas
A691: Niños Comunion | B691: unidad | C691: 2.53 € | D691: 100.00%
A692: Niscalo | B692: kg | C692: 3.00 € | D692: 100.00% | E692: Vegetales y frutas
A693: Nisperos | B693: kg | C693: 5.00 € | D693: 100.00% | E693: Vegetales y frutas
A694: Nueces Cascara | B694: kg | C694: 2.00 € | D694: 100.00% | E694: Vegetales y frutas
A695: Nueces Peladas | B695: kg | C695: 10.93 € | D695: 100.00% | E695: Vegetales y frutas
A696: Nuez Moscada | B696: kg | C696: 2.08 € | D696: 100.00% | E696: Secos y conservas
A697: Nuez Moscada | B697: unidad | C697: 1.94 € | D697: 100.00% | E697: Secos y conservas
A698: Ñames | B698: kg | C698: 5.40 € | D698: 100.00% | E698: Vegetales y frutas
A699: Ñoras | B699: kg | C699: 35.00 € | D699: 100.00% | E699: Vegetales y frutas
A700: Oregano | B700: kg | C700: 6.09 € | D700: 100.00% | E700: Vegetales y frutas
A701: Oregano | B701: manojo | C701: 1.00 € | D701: 100.00% | E701: Vegetales y frutas
A702: Orejones De Albaricoque | B702: kg | C702: 1.99 € | D702: 100.00% | E702: Secos y conservas
A703: Orejones De Tomate | B703: kg | C703: 18.00 € | D703: 100.00% | E703: Secos y conservas
...

Sheet MARGEN BRUTO
B2: MATERIAS PRIMAS | C2: GASTOS DE PERSONAL | D2: GASTOS GENERALES | E2: BENEFICIO
A3: PORCENTAJE | B3: 0.3 | C3: 0.18 | D3: 0.32 | E3: 0.2

Sheet RECETA1
B2: NOMBRE DE LA RECETA
B4: Restaurante: | F4: Categoría:
B6: Fecha: | C6: =TODAY() -> 46063 | F6: Precio de venta al público: | I6: =IF(I42="","",I8+I7)
B7: Tamaño de la ración: | F7: Impuestos: | H7: 0.07 | I7: =IF(I8="","",I8*H7/100%)
B8: Número de raciones: | F8: Precio de venta neto: | I8: =IF(I42="","",I42*100%/I11)
B10: Tiempo de preparación: | F10: Costo total de la receta: | I10: =IF(I42="","",I42)
B11: Tiempo de cocción: | F11: % Costo de la receta: | I11: =IF(I10="","",'MARGEN BRUTO'!B3)
B12: Temperatura de servicio: | F12: Margen de beneficio neto: | I12: =IF(I10="","",'MARGEN BRUTO'!E3)
B14: Ingredientes | C14: Medida | D14: Cantidad | E14: Coste | F14: Porcentaje de coste | G14: Rendimiento | H14: Coste total | I14: Coste real
D15: kg/L | E15: kg/Lt | I15: kg/Lt
C16: =IF(B16="","",VLOOKUP(B16,'LISTA DE PRECIOS INGREDIENTES'!A2:D1675,2,FALSE())) | E16: =IF(B16="","",VLOOKUP(B16,'LISTA DE PRECIOS INGREDIENTES'!A2:D1157,3,FALSE())) | F16: =IF(E16="","",H16*100%/$I$42) | G16: =IF(B16="","",VLOOKUP(B16,'LISTA DE PRECIOS INGREDIENTES'!A2:D1524,4,FALSE())) | H16: =IF(D16="","",(D16)*E16) | I16: =IF(G16="","",(D16*E16)*100%/G16)
C17: =IF(B17="","",VLOOKUP(B17,'LISTA DE PRECIOS INGREDIENTES'!A3:D1676,2,FALSE())) | E17: =IF(B17="","",VLOOKUP(B17,'LISTA DE PRECIOS INGREDIENTES'!A3:D1158,3,FALSE())) | F17: =IF(E17="","",H17*100%/$I$42) | G17: =IF(B17="","",VLOOKUP(B17,'LISTA DE PRECIOS INGREDIENTES'!A3:D1525,4,FALSE())) | H17: =IF(D17="","",(D17)*E17) | I17: =IF(G17="","",(D17*E17)*100%/G17)
C18: =IF(B18="","",VLOOKUP(B18,'LISTA DE PRECIOS INGREDIENTES'!A4:D1677,2,FALSE())) | E18: =IF(B18="","",VLOOKUP(B18,'LISTA DE PRECIOS INGREDIENTES'!A4:D1159,3,FALSE())) | F18: =IF(E18="","",H18*100%/$I$42) | G18: =IF(B18="","",VLOOKUP(B18,'LISTA DE PRECIOS INGREDIENTES'!A4:D1526,4,FALSE())) | H18: =IF(D18="","",(D18)*E18) | I18: =IF(G18="","",(D18*E18)*100%/G18)
C19: =IF(B19="","",VLOOKUP(B19,'LISTA DE PRECIOS INGREDIENTES'!A5:D1678,2,FALSE())) | E19: =IF(B19="","",VLOOKUP(B19,'LISTA DE PRECIOS INGREDIENTES'!A5:D1160,3,FALSE())) | F19: =IF(E19="","",H19*100%/$I$42) | G19: =IF(B19="","",VLOOKUP(B19,'LISTA DE PRECIOS INGREDIENTES'!A5:D1527,4,FALSE())) | H19: =IF(D19="","",(D19)*E19) | I19: =IF(G19="","",(D19*E19)*100%/G19)
C20: =IF(B20="","",VLOOKUP(B20,'LISTA DE PRECIOS INGREDIENTES'!A6:D1679,2,FALSE())) | E20: =IF(B20="","",VLOOKUP(B20,'LISTA DE PRECIOS INGREDIENTES'!A6:D1161,3,FALSE())) | F20: =IF(E20="","",H20*100%/$I$42) | G20: =IF(B20="","",VLOOKUP(B20,'LISTA DE PRECIOS INGREDIENTES'!A6:D1528,4,FALSE())) | H20: =IF(D20="","",(D20)*E20) | I20: =IF(G20="","",(D20*E20)*100%/G20)
C21: =IF(B21="","",VLOOKUP(B21,'LISTA DE PRECIOS INGREDIENTES'!A7:D1680,2,FALSE())) | E21: =IF(B21="","",VLOOKUP(B21,'LISTA DE PRECIOS INGREDIENTES'!A7:D1162,3,FALSE())) | F21: =IF(E21="","",H21*100%/$I$42) | G21: =IF(B21="","",VLOOKUP(B21,'LISTA DE PRECIOS INGREDIENTES'!A7:D1529,4,FALSE())) | H21: =IF(D21="","",(D21)*E21) | I21: =IF(G21="","",(D21*E21)*100%/G21)
C22: =IF(B22="","",VLOOKUP(B22,'LISTA DE PRECIOS INGREDIENTES'!A8:D1681,2,FALSE())) | E22: =IF(B22="","",VLOOKUP(B22,'LISTA DE PRECIOS INGREDIENTES'!A8:D1163,3,FALSE())) | F22: =IF(E22="","",H22*100%/$I$42) | G22: =IF(B22="","",VLOOKUP(B22,'LISTA DE PRECIOS INGREDIENTES'!A8:D1530,4,FALSE())) | H22: =IF(D22="","",(D22)*E22) | I22: =IF(G22="","",(D22*E22)*100%/G22)
C23: =IF(B23="","",VLOOKUP(B23,'LISTA DE PRECIOS INGREDIENTES'!A9:D1682,2,FALSE())) | E23: =IF(B23="","",VLOOKUP(B23,'LISTA DE PRECIOS INGREDIENTES'!A9:D1164,3,FALSE())) | F23: =IF(E23="","",H23*100%/$I$42) | G23: =IF(B23="","",VLOOKUP(B23,'LISTA DE PRECIOS INGREDIENTES'!A9:D1531,4,FALSE())) | H23: =IF(D23="","",(D23)*E23) | I23: =IF(G23="","",(D23*E23)*100%/G23)
C24: =IF(B24="","",VLOOKUP(B24,'LISTA DE PRECIOS INGREDIENTES'!A10:D1683,2,FALSE())) | E24: =IF(B24="","",VLOOKUP(B24,'LISTA DE PRECIOS INGREDIENTES'!A10:D1165,3,FALSE())) | F24: =IF(E24="","",H24*100%/$I$42) | G24: =IF(B24="","",VLOOKUP(B24,'LISTA DE PRECIOS INGREDIENTES'!A10:D1532,4,FALSE())) | H24: =IF(D24="","",(D24)*E24) | I24: =IF(G24="","",(D24*E24)*100%/G24)
C25: =IF(B25="","",VLOOKUP(B25,'LISTA DE PRECIOS INGREDIENTES'!A11:D1684,2,FALSE())) | E25: =IF(B25="","",VLOOKUP(B25,'LISTA DE PRECIOS INGREDIENTES'!A11:D1166,3,FALSE())) | F25: =IF(E25="","",H25*100%/$I$42) | G25: =IF(B25="","",VLOOKUP(B25,'LISTA DE PRECIOS INGREDIENTES'!A11:D1533,4,FALSE())) | H25: =IF(D25="","",(D25)*E25) | I25: =IF(G25="","",(D25*E25)*100%/G25)
C26: =IF(B26="","",VLOOKUP(B26,'LISTA DE PRECIOS INGREDIENTES'!A12:D1685,2,FALSE())) | E26: =IF(B26="","",VLOOKUP(B26,'LISTA DE PRECIOS INGREDIENTES'!A12:D1167,3,FALSE())) | F26: =IF(E26="","",H26*100%/$I$42) | G26: =IF(B26="","",VLOOKUP(B26,'LISTA DE PRECIOS INGREDIENTES'!A12:D1534,4,FALSE())) | H26: =IF(D26="","",(D26)*E26) | I26: =IF(G26="","",(D26*E26)*100%/G26)
C27: =IF(B27="","",VLOOKUP(B27,'LISTA DE PRECIOS INGREDIENTES'!A13:D1686,2,FALSE())) | E27: =IF(B27="","",VLOOKUP(B27,'LISTA DE PRECIOS INGREDIENTES'!A13:D1168,3,FALSE())) | F27: =IF(E27="","",H27*100%/$I$42) | G27: =IF(B27="","",VLOOKUP(B27,'LISTA DE PRECIOS INGREDIENTES'!A13:D1535,4,FALSE())) | H27: =IF(D27="","",(D27)*E27) | I27: =IF(G27="","",(D27*E27)*100%/G27)
C28: =IF(B28="","",VLOOKUP(B28,'LISTA DE PRECIOS INGREDIENTES'!A14:D1687,2,FALSE())) | E28: =IF(B28="","",VLOOKUP(B28,'LISTA DE PRECIOS INGREDIENTES'!A14:D1169,3,FALSE())) | F28: =IF(E28="","",H28*100%/$I$42) | G28: =IF(B28="","",VLOOKUP(B28,'LISTA DE PRECIOS INGREDIENTES'!A14:D1536,4,FALSE())) | H28: =IF(D28="","",(D28)*E28) | I28: =IF(G28="","",(D28*E28)*100%/G28)
E29: =IF(E16="","",SUM(E16:E28)) | G29: SUBTOTAL1 | H29: =IF(H16="","",(SUM(H16:H28))) | I29: =IF(I16="","",(SUM(I16:I28)))
B31: Materiales | C31: Medida | D31: Cantidad | E31: Coste | F31: Porcentaje de coste | G31: Rendimiento | H31: Coste total | I31: Coste real
I32: kg/Lt
C33: =IF(B33="","",VLOOKUP(B33,'LISTA DE PRECIOS MATERIALES'!A2:C156,2,FALSE())) | E33: =IF(B33="","",VLOOKUP(B33,'LISTA DE PRECIOS MATERIALES'!A2:C122,3,FALSE())) | F33: =IF(E33="","",(H33*100%/$I$42)) | H33: =IF(D33="","",(D33)*E33) | I33: =IF(G33="","",(D33*E33)*100%/G33)
E34: =IF(B34="","",VLOOKUP(B34,'LISTA DE PRECIOS MATERIALES'!A3:C123,3,FALSE())) | F34: =IF(E34="","",(H34*100%/$I$42)) | H34: =IF(D34="","",(D34)*E34) | I34: =IF(G34="","",(D34*E34)*100%/G34)
E35: =IF(B35="","",VLOOKUP(B35,'LISTA DE PRECIOS MATERIALES'!A4:C124,3,FALSE())) | F35: =IF(E35="","",(H35*100%/$I$42)) | H35: =IF(D35="","",(D35)*E35) | I35: =IF(G35="","",(D35*E35)*100%/G35)
E36: =IF(B36="","",VLOOKUP(B36,'LISTA DE PRECIOS MATERIALES'!A5:C125,3,FALSE())) | F36: =IF(E36="","",(H36*100%/$I$42)) | H36: =IF(D36="","",(D36)*E36) | I36: =IF(G36="","",(D36*E36)*100%/G36)
E37: =IF(B37="","",VLOOKUP(B37,'LISTA DE PRECIOS MATERIALES'!A6:C126,3,FALSE())) | F37: =IF(E37="","",(H37*100%/$I$42)) | H37: =IF(D37="","",(D37)*E37) | I37: =IF(G37="","",(D37*E37)*100%/G37)
E38: =IF(B38="","",VLOOKUP(B38,'LISTA DE PRECIOS MATERIALES'!A7:C127,3,FALSE())) | F38: =IF(E38="","",(H38*100%/$I$42)) | H38: =IF(D38="","",(D38)*E38) | I38: =IF(G38="","",(D38*E38)*100%/G38)
E39: =IF(B39="","",VLOOKUP(B39,'LISTA DE PRECIOS MATERIALES'!A8:C128,3,FALSE())) | F39: =IF(E39="","",(H39*100%/$I$42)) | H39: =IF(D39="","",(D39)*E39) | I39: =IF(G39="","",(D39*E39)*100%/G39)
E40: =SUM(E33:E39) -> 0 | G40: SUBTOTAL2 | H40: =IF(H33="","",SUM(H33:H39)) | I40: =IF(I33="","",SUM(I33:I39))
E41: =SUM(E16:E28) -> 0
B42: COSTO POR PERSONA | C42: =IF(C8="","",I43/C8) | E42: COSTO TOTAL DE LA RECETA | I42: =IF(H29="","",SUM(H29,H40))
E43: COSTO TOTAL REAL DE LA RECETA | I43: =IF(I29="","",SUM(I29,I40))
B45: Elaboración
B57: Presentación
B61: Equipo necesario para elaboración
...

Sheet RECETA 2
B2: NOMBRE DE LA RECETA
B4: Restaurante: | F4: Categoría:
B6: Fecha: | C6: =TODAY() -> 46063 | F6: Precio de venta al público: | I6: =IF(I42="","",I8+I7)
B7: Tamaño de la ración: | F7: Impuestos: | H7: 0.07 | I7: =IF(I8="","",I8*H7/100%)
B8: Número de raciones: | F8: Precio de venta neto: | I8: =IF(I42="","",I42*100%/I11)
B10: Tiempo de preparación: | F10: Costo total de la receta: | I10: =IF(I42="","",I42)
B11: Tiempo de cocción: | F11: % Costo de la receta: | I11: =IF(I10="","",'MARGEN BRUTO'!B3)
B12: Temperatura de servicio: | F12: Margen de beneficio neto: | I12: =IF(I10="","",'MARGEN BRUTO'!E3)
B14: Ingredientes | C14: Medida | D14: Cantidad | E14: Coste | F14: Porcentaje de coste | G14: Rendimiento | H14: Coste total | I14: Coste real
D15: kg/L | E15: kg/Lt | I15: kg/Lt
C16: =IF(B16="","",VLOOKUP(B16,'LISTA DE PRECIOS INGREDIENTES'!A2:D1675,2,FALSE())) | E16: =IF(B16="","",VLOOKUP(B16,'LISTA DE PRECIOS INGREDIENTES'!A2:D1157,3,FALSE())) | F16: =IF(E16="","",H16*100%/$I$42) | G16: =IF(B16="","",VLOOKUP(B16,'LISTA DE PRECIOS INGREDIENTES'!A2:D1524,4,FALSE())) | H16: =IF(D16="","",(D16)*E16) | I16: =IF(G16="","",(D16*E16)*100%/G16)
C17: =IF(B17="","",VLOOKUP(B17,'LISTA DE PRECIOS INGREDIENTES'!A3:D1676,2,FALSE())) | E17: =IF(B17="","",VLOOKUP(B17,'LISTA DE PRECIOS INGREDIENTES'!A3:D1158,3,FALSE())) | F17: =IF(E17="","",H17*100%/$I$42) | G17: =IF(B17="","",VLOOKUP(B17,'LISTA DE PRECIOS INGREDIENTES'!A3:D1525,4,FALSE())) | H17: =IF(D17="","",(D17)*E17) | I17: =IF(G17="","",(D17*E17)*100%/G17)
C18: =IF(B18="","",VLOOKUP(B18,'LISTA DE PRECIOS INGREDIENTES'!A4:D1677,2,FALSE())) | E18: =IF(B18="","",VLOOKUP(B18,'LISTA DE PRECIOS INGREDIENTES'!A4:D1159,3,FALSE())) | F18: =IF(E18="","",H18*100%/$I$42) | G18: =IF(B18="","",VLOOKUP(B18,'LISTA DE PRECIOS INGREDIENTES'!A4:D1526,4,FALSE())) | H18: =IF(D18="","",(D18)*E18) | I18: =IF(G18="","",(D18*E18)*100%/G18)
C19: =IF(B19="","",VLOOKUP(B19,'LISTA DE PRECIOS INGREDIENTES'!A5:D1678,2,FALSE())) | E19: =IF(B19="","",VLOOKUP(B19,'LISTA DE PRECIOS INGREDIENTES'!A5:D1160,3,FALSE())) | F19: =IF(E19="","",H19*100%/$I$42) | G19: =IF(B19="","",VLOOKUP(B19,'LISTA DE PRECIOS INGREDIENTES'!A5:D1527,4,FALSE())) | H19: =IF(D19="","",(D19)*E19) | I19: =IF(G19="","",(D19*E19)*100%/G19)
C20: =IF(B20="","",VLOOKUP(B20,'LISTA DE PRECIOS INGREDIENTES'!A6:D1679,2,FALSE())) | E20: =IF(B20="","",VLOOKUP(B20,'LISTA DE PRECIOS INGREDIENTES'!A6:D1161,3,FALSE())) | F20: =IF(E20="","",H20*100%/$I$42) | G20: =IF(B20="","",VLOOKUP(B20,'LISTA DE PRECIOS INGREDIENTES'!A6:D1528,4,FALSE())) | H20: =IF(D20="","",(D20)*E20) | I20: =IF(G20="","",(D20*E20)*100%/G20)
C21: =IF(B21="","",VLOOKUP(B21,'LISTA DE PRECIOS INGREDIENTES'!A7:D1680,2,FALSE())) | E21: =IF(B21="","",VLOOKUP(B21,'LISTA DE PRECIOS INGREDIENTES'!A7:D1162,3,FALSE())) | F21: =IF(E21="","",H21*100%/$I$42) | G21: =IF(B21="","",VLOOKUP(B21,'LISTA DE PRECIOS INGREDIENTES'!A7:D1529,4,FALSE())) | H21: =IF(D21="","",(D21)*E21) | I21: =IF(G21="","",(D21*E21)*100%/G21)
C22: =IF(B22="","",VLOOKUP(B22,'LISTA DE PRECIOS INGREDIENTES'!A8:D1681,2,FALSE())) | E22: =IF(B22="","",VLOOKUP(B22,'LISTA DE PRECIOS INGREDIENTES'!A8:D1163,3,FALSE())) | F22: =IF(E22="","",H22*100%/$I$42) | G22: =IF(B22="","",VLOOKUP(B22,'LISTA DE PRECIOS INGREDIENTES'!A8:D1530,4,FALSE())) | H22: =IF(D22="","",(D22)*E22) | I22: =IF(G22="","",(D22*E22)*100%/G22)
C23: =IF(B23="","",VLOOKUP(B23,'LISTA DE PRECIOS INGREDIENTES'!A9:D1682,2,FALSE())) | E23: =IF(B23="","",VLOOKUP(B23,'LISTA DE PRECIOS INGREDIENTES'!A9:D1164,3,FALSE())) | F23: =IF(E23="","",H23*100%/$I$42) | G23: =IF(B23="","",VLOOKUP(B23,'LISTA DE PRECIOS INGREDIENTES'!A9:D1531,4,FALSE())) | H23: =IF(D23="","",(D23)*E23) | I23: =IF(G23="","",(D23*E23)*100%/G23)
C24: =IF(B24="","",VLOOKUP(B24,'LISTA DE PRECIOS INGREDIENTES'!A10:D1683,2,FALSE())) | E24: =IF(B24="","",VLOOKUP(B24,'LISTA DE PRECIOS INGREDIENTES'!A10:D1165,3,FALSE())) | F24: =IF(E24="","",H24*100%/$I$42) | G24: =IF(B24="","",VLOOKUP(B24,'LISTA DE PRECIOS INGREDIENTES'!A10:D1532,4,FALSE())) | H24: =IF(D24="","",(D24)*E24) | I24: =IF(G24="","",(D24*E24)*100%/G24)
C25: =IF(B25="","",VLOOKUP(B25,'LISTA DE PRECIOS INGREDIENTES'!A11:D1684,2,FALSE())) | E25: =IF(B25="","",VLOOKUP(B25,'LISTA DE PRECIOS INGREDIENTES'!A11:D1166,3,FALSE())) | F25: =IF(E25="","",H25*100%/$I$42) | G25: =IF(B25="","",VLOOKUP(B25,'LISTA DE PRECIOS INGREDIENTES'!A11:D1533,4,FALSE())) | H25: =IF(D25="","",(D25)*E25) | I25: =IF(G25="","",(D25*E25)*100%/G25)
C26: =IF(B26="","",VLOOKUP(B26,'LISTA DE PRECIOS INGREDIENTES'!A12:D1685,2,FALSE())) | E26: =IF(B26="","",VLOOKUP(B26,'LISTA DE PRECIOS INGREDIENTES'!A12:D1167,3,FALSE())) | F26: =IF(E26="","",H26*100%/$I$42) | G26: =IF(B26="","",VLOOKUP(B26,'LISTA DE PRECIOS INGREDIENTES'!A12:D1534,4,FALSE())) | H26: =IF(D26="","",(D26)*E26) | I26: =IF(G26="","",(D26*E26)*100%/G26)
C27: =IF(B27="","",VLOOKUP(B27,'LISTA DE PRECIOS INGREDIENTES'!A13:D1686,2,FALSE())) | E27: =IF(B27="","",VLOOKUP(B27,'LISTA DE PRECIOS INGREDIENTES'!A13:D1168,3,FALSE())) | F27: =IF(E27="","",H27*100%/$I$42) | G27: =IF(B27="","",VLOOKUP(B27,'LISTA DE PRECIOS INGREDIENTES'!A13:D1535,4,FALSE())) | H27: =IF(D27="","",(D27)*E27) | I27: =IF(G27="","",(D27*E27)*100%/G27)
C28: =IF(B28="","",VLOOKUP(B28,'LISTA DE PRECIOS INGREDIENTES'!A14:D1687,2,FALSE())) | E28: =IF(B28="","",VLOOKUP(B28,'LISTA DE PRECIOS INGREDIENTES'!A14:D1169,3,FALSE())) | F28: =IF(E28="","",H28*100%/$I$42) | G28: =IF(B28="","",VLOOKUP(B28,'LISTA DE PRECIOS INGREDIENTES'!A14:D1536,4,FALSE())) | H28: =IF(D28="","",(D28)*E28) | I28: =IF(G28="","",(D28*E28)*100%/G28)
E29: =IF(E16="","",SUM(E16:E28)) | G29: SUBTOTAL1 | H29: =IF(H16="","",(SUM(H16:H28))) | I29: =IF(I16="","",(SUM(I16:I28)))
B31: Materiales | C31: Medida | D31: Cantidad | E31: Coste | F31: Porcentaje de coste | G31: Rendimiento | H31: Coste total | I31: Coste real
I32: kg/Lt
C33: =IF(B33="","",VLOOKUP(B33,'LISTA DE PRECIOS MATERIALES'!A2:C156,2,FALSE())) | E33: =IF(B33="","",VLOOKUP(B33,'LISTA DE PRECIOS MATERIALES'!A2:C122,3,FALSE())) | F33: =IF(E33="","",(H33*100%/$I$42)) | H33: =IF(D33="","",(D33)*E33) | I33: =IF(G33="","",(D33*E33)*100%/G33)
E34: =IF(B34="","",VLOOKUP(B34,'LISTA DE PRECIOS MATERIALES'!A3:C123,3,FALSE())) | F34: =IF(E34="","",(H34*100%/$I$42)) | H34: =IF(D34="","",(D34)*E34) | I34: =IF(G34="","",(D34*E34)*100%/G34)
E35: =IF(B35="","",VLOOKUP(B35,'LISTA DE PRECIOS MATERIALES'!A4:C124,3,FALSE())) | F35: =IF(E35="","",(H35*100%/$I$42)) | H35: =IF(D35="","",(D35)*E35) | I35: =IF(G35="","",(D35*E35)*100%/G35)
E36: =IF(B36="","",VLOOKUP(B36,'LISTA DE PRECIOS MATERIALES'!A5:C125,3,FALSE())) | F36: =IF(E36="","",(H36*100%/$I$42)) | H36: =IF(D36="","",(D36)*E36) | I36: =IF(G36="","",(D36*E36)*100%/G36)
E37: =IF(B37="","",VLOOKUP(B37,'LISTA DE PRECIOS MATERIALES'!A6:C126,3,FALSE())) | F37: =IF(E37="","",(H37*100%/$I$42)) | H37: =IF(D37="","",(D37)*E37) | I37: =IF(G37="","",(D37*E37)*100%/G37)
E38: =IF(B38="","",VLOOKUP(B38,'LISTA DE PRECIOS MATERIALES'!A7:C127,3,FALSE())) | F38: =IF(E38="","",(H38*100%/$I$42)) | H38: =IF(D38="","",(D38)*E38) | I38: =IF(G38="","",(D38*E38)*100%/G38)
E39: =IF(B39="","",VLOOKUP(B39,'LISTA DE PRECIOS MATERIALES'!A8:C128,3,FALSE())) | F39: =IF(E39="","",(H39*100%/$I$42)) | H39: =IF(D39="","",(D39)*E39) | I39: =IF(G39="","",(D39*E39)*100%/G39)
E40: =SUM(E33:E39) -> 0 | G40: SUBTOTAL2 | H40: =IF(H33="","",SUM(H33:H39)) | I40: =IF(I33="","",SUM(I33:I39))
E41: =SUM(E16:E28) -> 0
B42: COSTO POR PERSONA | C42: =IF(C8="","",I43/C8) | E42: COSTO TOTAL DE LA RECETA | I42: =IF(H29="","",SUM(H29,H40))
E43: COSTO TOTAL REAL DE LA RECETA | I43: =IF(I29="","",SUM(I29,I40))
B45: Elaboración
B57: Presentación
B61: Equipo necesario para elaboración
...

Sheet GILDA
B2: GILDA
B4: Restaurante: | C4: PEDAGÓGICO | F4: Categoría:
B6: Fecha: | C6: =TODAY() -> 46063 | F6: Precio de venta al público: | I6: =IF(I42="","",(I8+I7)/C8) -> #VALUE!
B7: Tamaño de la ración: | F7: Impuestos: | H7: 0.07 | I7: =IF(I8="","",I8*H7/100%) -> #VALUE!
B8: Número de raciones: | C8: 10 | F8: Precio de venta neto: | I8: =IF(I42="","",I42*100%/I11) -> #VALUE!
B10: Tiempo de preparación: | F10: Costo total de la receta: | I10: =IF(I42="","",I42) -> #VALUE!
B11: Tiempo de cocción: | F11: % Costo de la receta: | I11: =IF(I10="","",'MARGEN BRUTO'!B3) -> #VALUE!
B12: Temperatura de servicio: | F12: Margen de beneficio neto: | I12: =IF(I10="","",'MARGEN BRUTO'!E3) -> #VALUE!
B14: Ingredientes | C14: Medida | D14: Cantidad | E14: Coste | F14: Porcentaje de coste | G14: Rendimiento | H14: Coste total | I14: Coste real
D15: kg/L | E15: kg/Lt | I15: kg/Lt
B16: ACEITUNA VERDE SIN HUESO | C16: =IF(B16="","",VLOOKUP(B16,'LISTA DE PRECIOS INGREDIENTES'!A2:D1675,2,FALSE())) -> kg | D16: 0.4 | E16: =IF(B16="","",VLOOKUP(B16,'LISTA DE PRECIOS INGREDIENTES'!A2:D1157,3,FALSE())) -> 3.42 € | F16: =IF(E16="","",H16*100%/$I$42) -> #VALUE! | G16: =IF(B16="","",VLOOKUP(B16,'LISTA DE PRECIOS INGREDIENTES'!A2:D1524,4,FALSE())) -> 100.00% | H16: =IF(D16="","",(D16)*E16) -> #VALUE! | I16: =IF(G16="","",(D16*E16)*100%/G16) -> #VALUE!
B17: PIPARRA EN VINAGRE | C17: =IF(B17="","",VLOOKUP(B17,'LISTA DE PRECIOS INGREDIENTES'!A3:D1676,2,FALSE())) -> kg | D17: 0.3 | E17: =IF(B17="","",VLOOKUP(B17,'LISTA DE PRECIOS INGREDIENTES'!A3:D1158,3,FALSE())) -> 17.00 € | F17: =IF(E17="","",H17*100%/$I$42) -> #VALUE! | G17: =IF(B17="","",VLOOKUP(B17,'LISTA DE PRECIOS INGREDIENTES'!A3:D1525,4,FALSE())) -> 100.00% | H17: =IF(D17="","",(D17)*E17) -> #VALUE! | I17: =IF(G17="","",(D17*E17)*100%/G17) -> #VALUE!
B18: ANCHOAS CONSERVA | C18: =IF(B18="","",VLOOKUP(B18,'LISTA DE PRECIOS INGREDIENTES'!A4:D1677,2,FALSE())) -> kg | D18: 0.1 | E18: =IF(B18="","",VLOOKUP(B18,'LISTA DE PRECIOS INGREDIENTES'!A4:D1159,3,FALSE())) -> 44.28 € | F18: =IF(E18="","",H18*100%/$I$42) -> #VALUE! | G18: =IF(B18="","",VLOOKUP(B18,'LISTA DE PRECIOS INGREDIENTES'!A4:D1526,4,FALSE())) -> 100.00% | H18: =IF(D18="","",(D18)*E18) -> #VALUE! | I18: =IF(G18="","",(D18*E18)*100%/G18) -> #VALUE!
B19: aceite oliva virgen extra | C19: =IF(B19="","",VLOOKUP(B19,'LISTA DE PRECIOS INGREDIENTES'!A5:D1678,2,FALSE())) -> kg | D19: 0.05 | E19: =IF(B19="","",VLOOKUP(B19,'LISTA DE PRECIOS INGREDIENTES'!A5:D1160,3,FALSE())) -> 3.81 € | F19: =IF(E19="","",H19*100%/$I$42) -> #VALUE! | G19: =IF(B19="","",VLOOKUP(B19,'LISTA DE PRECIOS INGREDIENTES'!A5:D1527,4,FALSE())) -> 100.00% | H19: =IF(D19="","",(D19)*E19) -> #VALUE! | I19: =IF(G19="","",(D19*E19)*100%/G19) -> #VALUE!
C20: =IF(B20="","",VLOOKUP(B20,'LISTA DE PRECIOS INGREDIENTES'!A6:D1679,2,FALSE())) | E20: =IF(B20="","",VLOOKUP(B20,'LISTA DE PRECIOS INGREDIENTES'!A6:D1161,3,FALSE())) | F20: =IF(E20="","",H20*100%/$I$42) | G20: =IF(B20="","",VLOOKUP(B20,'LISTA DE PRECIOS INGREDIENTES'!A6:D1528,4,FALSE())) | H20: =IF(D20="","",(D20)*E20) | I20: =IF(G20="","",(D20*E20)*100%/G20)
C21: =IF(B21="","",VLOOKUP(B21,'LISTA DE PRECIOS INGREDIENTES'!A7:D1680,2,FALSE())) | E21: =IF(B21="","",VLOOKUP(B21,'LISTA DE PRECIOS INGREDIENTES'!A7:D1162,3,FALSE())) | F21: =IF(E21="","",H21*100%/$I$42) | G21: =IF(B21="","",VLOOKUP(B21,'LISTA DE PRECIOS INGREDIENTES'!A7:D1529,4,FALSE())) | H21: =IF(D21="","",(D21)*E21) | I21: =IF(G21="","",(D21*E21)*100%/G21)
C22: =IF(B22="","",VLOOKUP(B22,'LISTA DE PRECIOS INGREDIENTES'!A8:D1681,2,FALSE())) | E22: =IF(B22="","",VLOOKUP(B22,'LISTA DE PRECIOS INGREDIENTES'!A8:D1163,3,FALSE())) | F22: =IF(E22="","",H22*100%/$I$42) | G22: =IF(B22="","",VLOOKUP(B22,'LISTA DE PRECIOS INGREDIENTES'!A8:D1530,4,FALSE())) | H22: =IF(D22="","",(D22)*E22) | I22: =IF(G22="","",(D22*E22)*100%/G22)
C23: =IF(B23="","",VLOOKUP(B23,'LISTA DE PRECIOS INGREDIENTES'!A9:D1682,2,FALSE())) | E23: =IF(B23="","",VLOOKUP(B23,'LISTA DE PRECIOS INGREDIENTES'!A9:D1164,3,FALSE())) | F23: =IF(E23="","",H23*100%/$I$42) | G23: =IF(B23="","",VLOOKUP(B23,'LISTA DE PRECIOS INGREDIENTES'!A9:D1531,4,FALSE())) | H23: =IF(D23="","",(D23)*E23) | I23: =IF(G23="","",(D23*E23)*100%/G23)
C24: =IF(B24="","",VLOOKUP(B24,'LISTA DE PRECIOS INGREDIENTES'!A10:D1683,2,FALSE())) | E24: =IF(B24="","",VLOOKUP(B24,'LISTA DE PRECIOS INGREDIENTES'!A10:D1165,3,FALSE())) | F24: =IF(E24="","",H24*100%/$I$42) | G24: =IF(B24="","",VLOOKUP(B24,'LISTA DE PRECIOS INGREDIENTES'!A10:D1532,4,FALSE())) | H24: =IF(D24="","",(D24)*E24) | I24: =IF(G24="","",(D24*E24)*100%/G24)
C25: =IF(B25="","",VLOOKUP(B25,'LISTA DE PRECIOS INGREDIENTES'!A11:D1684,2,FALSE())) | E25: =IF(B25="","",VLOOKUP(B25,'LISTA DE PRECIOS INGREDIENTES'!A11:D1166,3,FALSE())) | F25: =IF(E25="","",H25*100%/$I$42) | G25: =IF(B25="","",VLOOKUP(B25,'LISTA DE PRECIOS INGREDIENTES'!A11:D1533,4,FALSE())) | H25: =IF(D25="","",(D25)*E25) | I25: =IF(G25="","",(D25*E25)*100%/G25)
C26: =IF(B26="","",VLOOKUP(B26,'LISTA DE PRECIOS INGREDIENTES'!A12:D1685,2,FALSE())) | E26: =IF(B26="","",VLOOKUP(B26,'LISTA DE PRECIOS INGREDIENTES'!A12:D1167,3,FALSE())) | F26: =IF(E26="","",H26*100%/$I$42) | G26: =IF(B26="","",VLOOKUP(B26,'LISTA DE PRECIOS INGREDIENTES'!A12:D1534,4,FALSE())) | H26: =IF(D26="","",(D26)*E26) | I26: =IF(G26="","",(D26*E26)*100%/G26)
C27: =IF(B27="","",VLOOKUP(B27,'LISTA DE PRECIOS INGREDIENTES'!A13:D1686,2,FALSE())) | E27: =IF(B27="","",VLOOKUP(B27,'LISTA DE PRECIOS INGREDIENTES'!A13:D1168,3,FALSE())) | F27: =IF(E27="","",H27*100%/$I$42) | G27: =IF(B27="","",VLOOKUP(B27,'LISTA DE PRECIOS INGREDIENTES'!A13:D1535,4,FALSE())) | H27: =IF(D27="","",(D27)*E27) | I27: =IF(G27="","",(D27*E27)*100%/G27)
C28: =IF(B28="","",VLOOKUP(B28,'LISTA DE PRECIOS INGREDIENTES'!A14:D1687,2,FALSE())) | E28: =IF(B28="","",VLOOKUP(B28,'LISTA DE PRECIOS INGREDIENTES'!A14:D1169,3,FALSE())) | F28: =IF(E28="","",H28*100%/$I$42) | G28: =IF(B28="","",VLOOKUP(B28,'LISTA DE PRECIOS INGREDIENTES'!A14:D1536,4,FALSE())) | H28: =IF(D28="","",(D28)*E28) | I28: =IF(G28="","",(D28*E28)*100%/G28)
E29: =IF(E16="","",SUM(E16:E28)) -> 0 | G29: SUBTOTAL1 | H29: =IF(H16="","",(SUM(H16:H28))) -> #VALUE! | I29: =IF(I16="","",(SUM(I16:I28))) -> #VALUE!
B31: Materiales | C31: Medida | D31: Cantidad | E31: Coste | F31: Porcentaje de coste | G31: Rendimiento | H31: Coste total | I31: Coste real
I32: kg/Lt
B33: BROCHETAS DE BAMBU | C33: =IF(B33="","",VLOOKUP(B33,'LISTA DE PRECIOS MATERIALES'!A2:C156,2,FALSE())) -> #N/A | D33: 12 | E33: =IF(B33="","",VLOOKUP(B33,'LISTA DE PRECIOS MATERIALES'!A2:C122,3,FALSE())) -> #N/A | F33: =IF(E33="","",(H33*100%/$I$42)) -> #N/A | H33: =IF(D33="","",(D33)*E33) -> #N/A | I33: =IF(G33="","",(D33*E33)*100%/G33)
E34: =IF(B34="","",VLOOKUP(B34,'LISTA DE PRECIOS MATERIALES'!A3:C123,3,FALSE())) | F34: =IF(E34="","",(H34*100%/$I$42)) | H34: =IF(D34="","",(D34)*E34) | I34: =IF(G34="","",(D34*E34)*100%/G34)
E35: =IF(B35="","",VLOOKUP(B35,'LISTA DE PRECIOS MATERIALES'!A4:C124,3,FALSE())) | F35: =IF(E35="","",(H35*100%/$I$42)) | H35: =IF(D35="","",(D35)*E35) | I35: =IF(G35="","",(D35*E35)*100%/G35)
E36: =IF(B36="","",VLOOKUP(B36,'LISTA DE PRECIOS MATERIALES'!A5:C125,3,FALSE())) | F36: =IF(E36="","",(H36*100%/$I$42)) | H36: =IF(D36="","",(D36)*E36) | I36: =IF(G36="","",(D36*E36)*100%/G36)
E37: =IF(B37="","",VLOOKUP(B37,'LISTA DE PRECIOS MATERIALES'!A6:C126,3,FALSE())) | F37: =IF(E37="","",(H37*100%/$I$42)) | H37: =IF(D37="","",(D37)*E37) | I37: =IF(G37="","",(D37*E37)*100%/G37)
E38: =IF(B38="","",VLOOKUP(B38,'LISTA DE PRECIOS MATERIALES'!A7:C127,3,FALSE())) | F38: =IF(E38="","",(H38*100%/$I$42)) | H38: =IF(D38="","",(D38)*E38) | I38: =IF(G38="","",(D38*E38)*100%/G38)
E39: =IF(B39="","",VLOOKUP(B39,'LISTA DE PRECIOS MATERIALES'!A8:C128,3,FALSE())) | F39: =IF(E39="","",(H39*100%/$I$42)) | H39: =IF(D39="","",(D39)*E39) | I39: =IF(G39="","",(D39*E39)*100%/G39)
E40: =SUM(E33:E39) -> #N/A | G40: SUBTOTAL2 | H40: =IF(H33="","",SUM(H33:H39)) -> #N/A | I40: =IF(I33="","",SUM(I33:I39))
E41: =SUM(E16:E28) -> 0
B42: COSTO POR PERSONA | C42: =IF(C8="","",I43/C8) -> #VALUE! | E42: COSTO TOTAL DE LA RECETA | I42: =IF(H29="","",SUM(H29,H40)) -> #VALUE!
E43: COSTO TOTAL REAL DE LA RECETA | I43: =IF(I29="","",SUM(I29,I40)) -> #VALUE!
B45: Elaboración
B57: Presentación
B61: Equipo necesario para elaboración
...

Sheet CROQUETA DE LANGOSTINOS
B2: NOMBRE DE LA RECETA
B4: Restaurante: | F4: Categoría:
B6: Fecha: | C6: =TODAY() -> 46063 | F6: Precio de venta al público: | I6: =IF(I42="","",(I8+I7)/C8) -> #VALUE!
B7: Tamaño de la ración: | F7: Impuestos: | H7: 0.07 | I7: =IF(I8="","",I8*H7/100%) -> #VALUE!
B8: Número de raciones: | C8: 30 | F8: Precio de venta neto: | I8: =IF(I42="","",I42*100%/I11) -> #VALUE!
B10: Tiempo de preparación: | F10: Costo total de la receta: | I10: =IF(I42="","",I42) -> #VALUE!
B11: Tiempo de cocción: | F11: % Costo de la receta: | I11: =IF(I10="","",'MARGEN BRUTO'!B3) -> #VALUE!
B12: Temperatura de servicio: | F12: Margen de beneficio neto: | I12: =IF(I10="","",'MARGEN BRUTO'!E3) -> #VALUE!
B14: Ingredientes | C14: Medida | D14: Cantidad | E14: Coste | F14: Porcentaje de coste | G14: Rendimiento | H14: Coste total | I14: Coste real
D15: kg/L | E15: kg/Lt | I15: kg/Lt
B16: LECHE ENTERA | C16: =IF(B16="","",VLOOKUP(B16,'LISTA DE PRECIOS INGREDIENTES'!A2:D1675,2,FALSE())) -> l | D16: 3 | E16: =IF(B16="","",VLOOKUP(B16,'LISTA DE PRECIOS INGREDIENTES'!A2:D1157,3,FALSE())) -> 0.55 € | F16: =IF(E16="","",H16*100%/$I$42) -> #VALUE! | G16: =IF(B16="","",VLOOKUP(B16,'LISTA DE PRECIOS INGREDIENTES'!A2:D1524,4,FALSE())) -> 100.00% | H16: =IF(D16="","",(D16)*E16) -> #VALUE! | I16: =IF(G16="","",(D16*E16)*100%/G16) -> #VALUE!
B17: FUMET | C17: =IF(B17="","",VLOOKUP(B17,'LISTA DE PRECIOS INGREDIENTES'!A3:D1676,2,FALSE())) -> l | D17: 0.4 | E17: =IF(B17="","",VLOOKUP(B17,'LISTA DE PRECIOS INGREDIENTES'!A3:D1158,3,FALSE())) -> 4.50 € | F17: =IF(E17="","",H17*100%/$I$42) -> #VALUE! | G17: =IF(B17="","",VLOOKUP(B17,'LISTA DE PRECIOS INGREDIENTES'!A3:D1525,4,FALSE())) -> 100.00% | H17: =IF(D17="","",(D17)*E17) -> #VALUE! | I17: =IF(G17="","",(D17*E17)*100%/G17) -> #VALUE!
B18: harina floja | C18: =IF(B18="","",VLOOKUP(B18,'LISTA DE PRECIOS INGREDIENTES'!A4:D1677,2,FALSE())) -> kg | D18: 0.7 | E18: =IF(B18="","",VLOOKUP(B18,'LISTA DE PRECIOS INGREDIENTES'!A4:D1159,3,FALSE())) -> 0.53 € | F18: =IF(E18="","",H18*100%/$I$42) -> #VALUE! | G18: =IF(B18="","",VLOOKUP(B18,'LISTA DE PRECIOS INGREDIENTES'!A4:D1526,4,FALSE())) -> 100.00% | H18: =IF(D18="","",(D18)*E18) -> #VALUE! | I18: =IF(G18="","",(D18*E18)*100%/G18) -> #VALUE!
B19: MANTEQUILLA | C19: =IF(B19="","",VLOOKUP(B19,'LISTA DE PRECIOS INGREDIENTES'!A5:D1678,2,FALSE())) -> #N/A | D19: 0.7 | E19: =IF(B19="","",VLOOKUP(B19,'LISTA DE PRECIOS INGREDIENTES'!A5:D1160,3,FALSE())) -> #N/A | F19: =IF(E19="","",H19*100%/$I$42) -> #N/A | G19: =IF(B19="","",VLOOKUP(B19,'LISTA DE PRECIOS INGREDIENTES'!A5:D1527,4,FALSE())) -> #N/A | H19: =IF(D19="","",(D19)*E19) -> #N/A | I19: =IF(G19="","",(D19*E19)*100%/G19) -> #N/A
B20: langostino 3 | C20: =IF(B20="","",VLOOKUP(B20,'LISTA DE PRECIOS INGREDIENTES'!A6:D1679,2,FALSE())) -> kg | D20: 1 | E20: =IF(B20="","",VLOOKUP(B20,'LISTA DE PRECIOS INGREDIENTES'!A6:D1161,3,FALSE())) -> 7.75 € | F20: =IF(E20="","",H20*100%/$I$42) -> #VALUE! | G20: =IF(B20="","",VLOOKUP(B20,'LISTA DE PRECIOS INGREDIENTES'!A6:D1528,4,FALSE())) -> 100.00% | H20: =IF(D20="","",(D20)*E20) -> #VALUE! | I20: =IF(G20="","",(D20*E20)*100%/G20) -> #VALUE!
B21: pimiento rojo | C21: =IF(B21="","",VLOOKUP(B21,'LISTA DE PRECIOS INGREDIENTES'!A7:D1680,2,FALSE())) -> kg | D21: 0.1 | E21: =IF(B21="","",VLOOKUP(B21,'LISTA DE PRECIOS INGREDIENTES'!A7:D1162,3,FALSE())) -> 2.40 € | F21: =IF(E21="","",H21*100%/$I$42) -> #VALUE! | G21: =IF(B21="","",VLOOKUP(B21,'LISTA DE PRECIOS INGREDIENTES'!A7:D1529,4,FALSE())) -> 100.00% | H21: =IF(D21="","",(D21)*E21) -> #VALUE! | I21: =IF(G21="","",(D21*E21)*100%/G21) -> #VALUE!
B22: ajos granel | C22: =IF(B22="","",VLOOKUP(B22,'LISTA DE PRECIOS INGREDIENTES'!A8:D1681,2,FALSE())) -> kg | D22: 0.05 | E22: =IF(B22="","",VLOOKUP(B22,'LISTA DE PRECIOS INGREDIENTES'!A8:D1163,3,FALSE())) -> 2.70 € | F22: =IF(E22="","",H22*100%/$I$42) -> #VALUE! | G22: =IF(B22="","",VLOOKUP(B22,'LISTA DE PRECIOS INGREDIENTES'!A8:D1530,4,FALSE())) -> 100.00% | H22: =IF(D22="","",(D22)*E22) -> #VALUE! | I22: =IF(G22="","",(D22*E22)*100%/G22) -> #VALUE!
C23: =IF(B23="","",VLOOKUP(B23,'LISTA DE PRECIOS INGREDIENTES'!A9:D1682,2,FALSE())) | E23: =IF(B23="","",VLOOKUP(B23,'LISTA DE PRECIOS INGREDIENTES'!A9:D1164,3,FALSE())) | F23: =IF(E23="","",H23*100%/$I$42) | G23: =IF(B23="","",VLOOKUP(B23,'LISTA DE PRECIOS INGREDIENTES'!A9:D1531,4,FALSE())) | H23: =IF(D23="","",(D23)*E23) | I23: =IF(G23="","",(D23*E23)*100%/G23)
C24: =IF(B24="","",VLOOKUP(B24,'LISTA DE PRECIOS INGREDIENTES'!A10:D1683,2,FALSE())) | E24: =IF(B24="","",VLOOKUP(B24,'LISTA DE PRECIOS INGREDIENTES'!A10:D1165,3,FALSE())) | F24: =IF(E24="","",H24*100%/$I$42) | G24: =IF(B24="","",VLOOKUP(B24,'LISTA DE PRECIOS INGREDIENTES'!A10:D1532,4,FALSE())) | H24: =IF(D24="","",(D24)*E24) | I24: =IF(G24="","",(D24*E24)*100%/G24)
C25: =IF(B25="","",VLOOKUP(B25,'LISTA DE PRECIOS INGREDIENTES'!A11:D1684,2,FALSE())) | E25: =IF(B25="","",VLOOKUP(B25,'LISTA DE PRECIOS INGREDIENTES'!A11:D1166,3,FALSE())) | F25: =IF(E25="","",H25*100%/$I$42) | G25: =IF(B25="","",VLOOKUP(B25,'LISTA DE PRECIOS INGREDIENTES'!A11:D1533,4,FALSE())) | H25: =IF(D25="","",(D25)*E25) | I25: =IF(G25="","",(D25*E25)*100%/G25)
C26: =IF(B26="","",VLOOKUP(B26,'LISTA DE PRECIOS INGREDIENTES'!A12:D1685,2,FALSE())) | E26: =IF(B26="","",VLOOKUP(B26,'LISTA DE PRECIOS INGREDIENTES'!A12:D1167,3,FALSE())) | F26: =IF(E26="","",H26*100%/$I$42) | G26: =IF(B26="","",VLOOKUP(B26,'LISTA DE PRECIOS INGREDIENTES'!A12:D1534,4,FALSE())) | H26: =IF(D26="","",(D26)*E26) | I26: =IF(G26="","",(D26*E26)*100%/G26)
C27: =IF(B27="","",VLOOKUP(B27,'LISTA DE PRECIOS INGREDIENTES'!A13:D1686,2,FALSE())) | E27: =IF(B27="","",VLOOKUP(B27,'LISTA DE PRECIOS INGREDIENTES'!A13:D1168,3,FALSE())) | F27: =IF(E27="","",H27*100%/$I$42) | G27: =IF(B27="","",VLOOKUP(B27,'LISTA DE PRECIOS INGREDIENTES'!A13:D1535,4,FALSE())) | H27: =IF(D27="","",(D27)*E27) | I27: =IF(G27="","",(D27*E27)*100%/G27)
C28: =IF(B28="","",VLOOKUP(B28,'LISTA DE PRECIOS INGREDIENTES'!A14:D1687,2,FALSE())) | E28: =IF(B28="","",VLOOKUP(B28,'LISTA DE PRECIOS INGREDIENTES'!A14:D1169,3,FALSE())) | F28: =IF(E28="","",H28*100%/$I$42) | G28: =IF(B28="","",VLOOKUP(B28,'LISTA DE PRECIOS INGREDIENTES'!A14:D1536,4,FALSE())) | H28: =IF(D28="","",(D28)*E28) | I28: =IF(G28="","",(D28*E28)*100%/G28)
E29: =IF(E16="","",SUM(E16:E28)) -> #N/A | G29: SUBTOTAL1 | H29: =IF(H16="","",(SUM(H16:H28))) -> #VALUE! | I29: =IF(I16="","",(SUM(I16:I28))) -> #VALUE!
B31: Materiales | C31: Medida | D31: Cantidad | E31: Coste | F31: Porcentaje de coste | G31: Rendimiento | H31: Coste total | I31: Coste real
I32: kg/Lt
C33: =IF(B33="","",VLOOKUP(B33,'LISTA DE PRECIOS MATERIALES'!A2:C156,2,FALSE())) | E33: =IF(B33="","",VLOOKUP(B33,'LISTA DE PRECIOS MATERIALES'!A2:C122,3,FALSE())) | F33: =IF(E33="","",(H33*100%/$I$42)) | H33: =IF(D33="","",(D33)*E33) | I33: =IF(G33="","",(D33*E33)*100%/G33)
E34: =IF(B34="","",VLOOKUP(B34,'LISTA DE PRECIOS MATERIALES'!A3:C123,3,FALSE())) | F34: =IF(E34="","",(H34*100%/$I$42)) | H34: =IF(D34="","",(D34)*E34) | I34: =IF(G34="","",(D34*E34)*100%/G34)
E35: =IF(B35="","",VLOOKUP(B35,'LISTA DE PRECIOS MATERIALES'!A4:C124,3,FALSE())) | F35: =IF(E35="","",(H35*100%/$I$42)) | H35: =IF(D35="","",(D35)*E35) | I35: =IF(G35="","",(D35*E35)*100%/G35)
E36: =IF(B36="","",VLOOKUP(B36,'LISTA DE PRECIOS MATERIALES'!A5:C125,3,FALSE())) | F36: =IF(E36="","",(H36*100%/$I$42)) | H36: =IF(D36="","",(D36)*E36) | I36: =IF(G36="","",(D36*E36)*100%/G36)
E37: =IF(B37="","",VLOOKUP(B37,'LISTA DE PRECIOS MATERIALES'!A6:C126,3,FALSE())) | F37: =IF(E37="","",(H37*100%/$I$42)) | H37: =IF(D37="","",(D37)*E37) | I37: =IF(G37="","",(D37*E37)*100%/G37)
E38: =IF(B38="","",VLOOKUP(B38,'LISTA DE PRECIOS MATERIALES'!A7:C127,3,FALSE())) | F38: =IF(E38="","",(H38*100%/$I$42)) | H38: =IF(D38="","",(D38)*E38) | I38: =IF(G38="","",(D38*E38)*100%/G38)
E39: =IF(B39="","",VLOOKUP(B39,'LISTA DE PRECIOS MATERIALES'!A8:C128,3,FALSE())) | F39: =IF(E39="","",(H39*100%/$I$42)) | H39: =IF(D39="","",(D39)*E39) | I39: =IF(G39="","",(D39*E39)*100%/G39)
E40: =SUM(E33:E39) -> 0 | G40: SUBTOTAL2 | H40: =IF(H33="","",SUM(H33:H39)) | I40: =IF(I33="","",SUM(I33:I39))
E41: =SUM(E16:E28) -> #N/A
B42: COSTO POR PERSONA | C42: =IF(C8="","",I43/C8) -> #VALUE! | E42: COSTO TOTAL DE LA RECETA | I42: =IF(H29="","",SUM(H29,H40)) -> #VALUE!
E43: COSTO TOTAL REAL DE LA RECETA | I43: =IF(I29="","",SUM(I29,I40)) -> #VALUE!
B45: Elaboración
B63: Presentación
B67: Equipo necesario para elaboración
...

Sheet CREMA DE CALABAZA Y COCO
B2: CREMA DE CALABAZA CON LECHE DE COCO
B4: Restaurante: | F4: Categoría:
B6: Fecha: | C6: =TODAY() -> 46063 | F6: Precio de venta al público: | I6: =IF(I42="","",(I8+I7)/C8) -> #VALUE!
B7: Tamaño de la ración: | F7: Impuestos: | H7: 0.07 | I7: =IF(I8="","",I8*H7/100%) -> #VALUE!
B8: Número de raciones: | C8: 30 | F8: Precio de venta neto: | I8: =IF(I42="","",I42*100%/I11) -> #VALUE!
B10: Tiempo de preparación: | F10: Costo total de la receta: | I10: =IF(I42="","",I42) -> #VALUE!
B11: Tiempo de cocción: | F11: % Costo de la receta: | I11: =IF(I10="","",'MARGEN BRUTO'!B3) -> #VALUE!
B12: Temperatura de servicio: | F12: Margen de beneficio neto: | I12: =IF(I10="","",'MARGEN BRUTO'!E3) -> #VALUE!
B14: Ingredientes | C14: Medida | D14: Cantidad | E14: Coste | F14: Porcentaje de coste | G14: Rendimiento | H14: Coste total | I14: Coste real
D15: kg/L | E15: kg/Lt | I15: kg/Lt
B16: calabaza | C16: =IF(B16="","",VLOOKUP(B16,'LISTA DE PRECIOS INGREDIENTES'!A2:D1675,2,FALSE())) -> kg | D16: 8 | E16: =IF(B16="","",VLOOKUP(B16,'LISTA DE PRECIOS INGREDIENTES'!A2:D1157,3,FALSE())) -> 0.57 € | F16: =IF(E16="","",H16*100%/$I$42) -> #VALUE! | G16: =IF(B16="","",VLOOKUP(B16,'LISTA DE PRECIOS INGREDIENTES'!A2:D1524,4,FALSE())) -> 100.00% | H16: =IF(D16="","",(D16)*E16) -> #VALUE! | I16: =IF(G16="","",(D16*E16)*100%/G16) -> #VALUE!
B17: puerros | C17: =IF(B17="","",VLOOKUP(B17,'LISTA DE PRECIOS INGREDIENTES'!A3:D1676,2,FALSE())) -> kg | D17: 1 | E17: =IF(B17="","",VLOOKUP(B17,'LISTA DE PRECIOS INGREDIENTES'!A3:D1158,3,FALSE())) -> 1.69 € | F17: =IF(E17="","",H17*100%/$I$42) -> #VALUE! | G17: =IF(B17="","",VLOOKUP(B17,'LISTA DE PRECIOS INGREDIENTES'!A3:D1525,4,FALSE())) -> 100.00% | H17: =IF(D17="","",(D17)*E17) -> #VALUE! | I17: =IF(G17="","",(D17*E17)*100%/G17) -> #VALUE!
B18: cebolla blanca | C18: =IF(B18="","",VLOOKUP(B18,'LISTA DE PRECIOS INGREDIENTES'!A4:D1677,2,FALSE())) -> kg | D18: 1.5 | E18: =IF(B18="","",VLOOKUP(B18,'LISTA DE PRECIOS INGREDIENTES'!A4:D1159,3,FALSE())) -> 0.76 € | F18: =IF(E18="","",H18*100%/$I$42) -> #VALUE! | G18: =IF(B18="","",VLOOKUP(B18,'LISTA DE PRECIOS INGREDIENTES'!A4:D1526,4,FALSE())) -> 100.00% | H18: =IF(D18="","",(D18)*E18) -> #VALUE! | I18: =IF(G18="","",(D18*E18)*100%/G18) -> #VALUE!
B19: zanahoria | C19: =IF(B19="","",VLOOKUP(B19,'LISTA DE PRECIOS INGREDIENTES'!A5:D1678,2,FALSE())) -> kg | D19: 1 | E19: =IF(B19="","",VLOOKUP(B19,'LISTA DE PRECIOS INGREDIENTES'!A5:D1160,3,FALSE())) -> 0.63 € | F19: =IF(E19="","",H19*100%/$I$42) -> #VALUE! | G19: =IF(B19="","",VLOOKUP(B19,'LISTA DE PRECIOS INGREDIENTES'!A5:D1527,4,FALSE())) -> 100.00% | H19: =IF(D19="","",(D19)*E19) -> #VALUE! | I19: =IF(G19="","",(D19*E19)*100%/G19) -> #VALUE!
B20: papa arrugar | C20: =IF(B20="","",VLOOKUP(B20,'LISTA DE PRECIOS INGREDIENTES'!A6:D1679,2,FALSE())) -> kg | D20: 1.5 | E20: =IF(B20="","",VLOOKUP(B20,'LISTA DE PRECIOS INGREDIENTES'!A6:D1161,3,FALSE())) -> 0.82 € | F20: =IF(E20="","",H20*100%/$I$42) -> #VALUE! | G20: =IF(B20="","",VLOOKUP(B20,'LISTA DE PRECIOS INGREDIENTES'!A6:D1528,4,FALSE())) -> 100.00% | H20: =IF(D20="","",(D20)*E20) -> #VALUE! | I20: =IF(G20="","",(D20*E20)*100%/G20) -> #VALUE!
B21: LECHE DE COCO | C21: =IF(B21="","",VLOOKUP(B21,'LISTA DE PRECIOS INGREDIENTES'!A7:D1680,2,FALSE())) -> l | D21: 0.1 | E21: =IF(B21="","",VLOOKUP(B21,'LISTA DE PRECIOS INGREDIENTES'!A7:D1162,3,FALSE())) -> 2.90 € | F21: =IF(E21="","",H21*100%/$I$42) -> #VALUE! | G21: =IF(B21="","",VLOOKUP(B21,'LISTA DE PRECIOS INGREDIENTES'!A7:D1529,4,FALSE())) -> 100.00% | H21: =IF(D21="","",(D21)*E21) -> #VALUE! | I21: =IF(G21="","",(D21*E21)*100%/G21) -> #VALUE!
B22: coco rallado | C22: =IF(B22="","",VLOOKUP(B22,'LISTA DE PRECIOS INGREDIENTES'!A8:D1681,2,FALSE())) -> kg | D22: 0.1 | E22: =IF(B22="","",VLOOKUP(B22,'LISTA DE PRECIOS INGREDIENTES'!A8:D1163,3,FALSE())) -> 4.17 € | F22: =IF(E22="","",H22*100%/$I$42) -> #VALUE! | G22: =IF(B22="","",VLOOKUP(B22,'LISTA DE PRECIOS INGREDIENTES'!A8:D1530,4,FALSE())) -> 100.00% | H22: =IF(D22="","",(D22)*E22) -> #VALUE! | I22: =IF(G22="","",(D22*E22)*100%/G22) -> #VALUE!
C23: =IF(B23="","",VLOOKUP(B23,'LISTA DE PRECIOS INGREDIENTES'!A9:D1682,2,FALSE())) | E23: =IF(B23="","",VLOOKUP(B23,'LISTA DE PRECIOS INGREDIENTES'!A9:D1164,3,FALSE())) | F23: =IF(E23="","",H23*100%/$I$42) | G23: =IF(B23="","",VLOOKUP(B23,'LISTA DE PRECIOS INGREDIENTES'!A9:D1531,4,FALSE())) | H23: =IF(D23="","",(D23)*E23) | I23: =IF(G23="","",(D23*E23)*100%/G23)
C24: =IF(B24="","",VLOOKUP(B24,'LISTA DE PRECIOS INGREDIENTES'!A10:D1683,2,FALSE())) | E24: =IF(B24="","",VLOOKUP(B24,'LISTA DE PRECIOS INGREDIENTES'!A10:D1165,3,FALSE())) | F24: =IF(E24="","",H24*100%/$I$42) | G24: =IF(B24="","",VLOOKUP(B24,'LISTA DE PRECIOS INGREDIENTES'!A10:D1532,4,FALSE())) | H24: =IF(D24="","",(D24)*E24) | I24: =IF(G24="","",(D24*E24)*100%/G24)
